<?xml version="1.0" ?>
<!-- =================================================================================== -->
<!-- |    This document was autogenerated by xacro from ./robot/moma_robot.xacro       | -->
<!-- |    EDITING THIS FILE BY HAND IS NOT RECOMMENDED                                 | -->
<!-- =================================================================================== -->
<robot name="moma_robot" xmlns:xacro="http://ros.org/wiki/xacro">
  <material name="Blue">
    <color rgba="0.0 0.0 0.8 1.0"/>
  </material>
  <material name="LightBlue">
    <color rgba="0.4 0.5 1.0 1.0"/>
  </material>
  <material name="DeepBlue">
    <color rgba="0.2 0.3 0.7 1.0"/>
  </material>
  <material name="Green">
    <color rgba="0.0 0.8 0.0 1.0"/>
  </material>
  <material name="Grey">
    <color rgba="0.7 0.7 0.7 1.0"/>
  </material>
  <material name="Grey2">
    <color rgba="0.9 0.9 0.9 1.0"/>
  </material>
  <material name="Red">
    <color rgba="0.8 0.0 0.0 1.0"/>
  </material>
  <material name="White">
    <color rgba="1.0 1.0 1.0 1.0"/>
  </material>
  <material name="Black">
    <color rgba="0.1 0.1 0.1 1.0"/>
  </material>
  <material name="LightGrey">
    <color rgba="0.6 0.6 0.6 1.0"/>
  </material>
  <material name="Caster">
    <texture filename="package://pr2_description/materials/textures/pr2_caster_texture.png"/>
  </material>
  
  <link name="base_footprint">
    <visual>
      <geometry>
        <mesh filename="package://robot_bringup/description/meshes/moma_model_mesh/moma_mobile_base_visual.dae"/>
      </geometry>
      <origin rpy="0 0 3.14159265359" xyz="0.0 0.0 0.0"/>
      <material name="DeepBlue"/>
    </visual>
    <collision>
      <geometry>
        <mesh filename="package://robot_bringup/description/meshes/moma_model_mesh/moma_mobile_base_collision.stl"/>
      </geometry>
      <origin rpy="0 0 0" xyz="0.0 0.0 0.0"/>
    </collision>
  </link>
  <joint name="fl_wheel_joint" type="fixed">
    <origin rpy="0 0 0" xyz="0.2575 0.2235 0.06"/>
    <parent link="base_footprint"/>
    <child link="fl_wheel_link"/>
    <axis xyz="0 1 0"/>
  </joint>
  <link name="fl_wheel_link">
    <visual>
      <geometry>
        <mesh filename="package://robot_bringup/description/meshes/moma_model_mesh/moma_wheel_visual.dae"/>
      </geometry>
      <origin rpy="0 0 0" xyz="0.0 0.0 0.0"/>
      <material name="LightBlue"/>
    </visual>
    <collision>
      <geometry>
        <cylinder length="0.045" radius="0.052"/>
      </geometry>
      <origin rpy="1.57079632679 0 0" xyz="0.0 0.0 0.0"/>
    </collision>
  </link>
  <joint name="fr_wheel_joint" type="fixed">
    <origin rpy="0 0 0" xyz="0.2575 -0.2235 0.06"/>
    <parent link="base_footprint"/>
    <child link="fr_wheel_link"/>
    <axis xyz="0 1 0"/>
  </joint>
  <link name="fr_wheel_link">
    <visual>
      <geometry>
        <mesh filename="package://robot_bringup/description/meshes/moma_model_mesh/moma_wheel_visual.dae"/>
      </geometry>
      <origin rpy="0 0 0" xyz="0.0 0.0 0.0"/>
      <material name="LightBlue"/>
    </visual>
    <collision>
      <geometry>
        <cylinder length="0.045" radius="0.052"/>
      </geometry>
      <origin rpy="1.57079632679 0 0" xyz="0.0 0.0 0.0"/>
    </collision>
  </link>
  <joint name="bl_wheel_joint" type="fixed">
    <origin rpy="0 0 0" xyz="-0.2575 0.2235 0.06"/>
    <parent link="base_footprint"/>
    <child link="bl_wheel_link"/>
    <axis xyz="0 1 0"/>
  </joint>
  <link name="bl_wheel_link">
    <visual>
      <geometry>
        <mesh filename="package://robot_bringup/description/meshes/moma_model_mesh/moma_wheel_visual.dae"/>
      </geometry>
      <origin rpy="0 0 0" xyz="0.0 0.0 0.0"/>
      <material name="LightBlue"/>
    </visual>
    <collision>
      <geometry>
        <cylinder length="0.045" radius="0.052"/>
      </geometry>
      <origin rpy="1.57079632679 0 0" xyz="0.0 0.0 0.0"/>
    </collision>
  </link>
  <joint name="br_wheel_joint" type="fixed">
    <origin rpy="0 0 0" xyz="-0.2575 -0.2235 0.06"/>
    <parent link="base_footprint"/>
    <child link="br_wheel_link"/>
    <axis xyz="0 1 0"/>
  </joint>
  <link name="br_wheel_link">
    <visual>
      <geometry>
        <mesh filename="package://robot_bringup/description/meshes/moma_model_mesh/moma_wheel_visual.dae"/>
      </geometry>
      <origin rpy="0 0 0" xyz="0.0 0.0 0.0"/>
      <material name="LightBlue"/>
    </visual>
    <collision>
      <geometry>
        <cylinder length="0.045" radius="0.052"/>
      </geometry>
      <origin rpy="1.57079632679 0 0" xyz="0.0 0.0 0.0"/>
    </collision>
  </link>
  <joint name="F_lidar_joint" type="fixed">
    <parent link="base_footprint"/>
    <child link="F_lidar_link"/>
    <origin rpy="3.14159265359 0.0 0.628318530716" xyz="0.181 0.17285 0.13625"/>
  </joint>
  <link name="F_lidar_link">
    <visual>
      <geometry>
        <box size="0.04 0.04 0.08"/>
      </geometry>
      <origin rpy="0 0 0" xyz="0.0 0.0 0.0"/>
      <material name="LightBlue"/>
    </visual>
    <collision>
      <geometry>
        <box size="0.04 0.04 0.08"/>
      </geometry>
      <origin rpy="0 0 0" xyz="0.0 0.0 0.0"/>
      <material name="LightBlue"/>
    </collision>
  </link>
  <joint name="B_lidar_joint" type="fixed">
    <parent link="base_footprint"/>
    <child link="B_lidar_link"/>
    <origin rpy="3.14159265359 0.0 -2.51327412286" xyz="-0.181 -0.17285 0.13625"/>
  </joint>
  <link name="B_lidar_link">
    <visual>
      <geometry>
        <box size="0.04 0.04 0.08"/>
      </geometry>
      <origin rpy="0 0 0" xyz="0.0 0.0 0.0"/>
      <material name="LightBlue"/>
    </visual>
    <collision>
      <geometry>
        <box size="0.04 0.04 0.08"/>
      </geometry>
      <origin rpy="0 0 0" xyz="0.0 0.0 0.0"/>
      <material name="LightBlue"/>
    </collision>
  </link>
  <joint name="lift_base_joint" type="fixed">
    <parent link="base_footprint"/>
    <child link="lift_fix_link"/>
    <origin rpy="0.0 0.0 0.0" xyz="0.0 0.0 0.318"/>
  </joint>
  <link name="lift_fix_link">
    <visual>
      <geometry>
        <box size="0.10 0.10 0.37"/>
      </geometry>
      <origin rpy="0 0 0" xyz="0.0 0.0 0.185"/>
      <material name="Grey"/>
    </visual>
    <collision>
      <geometry>
        <box size="0.10 0.10 0.37"/>
      </geometry>
      <origin rpy="0 0 0" xyz="0.0 0.0 0.185"/>
    </collision>
  </link>
  <joint name="lift_move_joint" type="fixed">
    <parent link="lift_fix_link"/>
    <child link="lift_move_link"/>
    <origin rpy="0.0 0.0 0.0" xyz="0.0 0.0 0.0"/>
    <limit effort="250" lower="0.0" upper="0.25" velocity="0.5"/>
    <axis xyz="0 0 1"/>
  </joint>
  <link name="lift_move_link">
    <visual>
      <geometry>
        <box size="0.14 0.14 0.37"/>
      </geometry>
      <origin rpy="0 0 0" xyz="0.0 0.0 0.185"/>
      <material name="Grey"/>
    </visual>
    <collision>
      <geometry>
        <box size="0.14 0.14 0.37"/>
      </geometry>
      <origin rpy="0 0 0" xyz="0.0 0.0 0.185"/>
    </collision>
  </link>
  <joint name="global_camera_joint" type="fixed">
    <parent link="lift_move_link"/>
    <child link="global_camera_link"/>
    <origin rpy="0.0 0.0 0.0" xyz="0.15 0.0 0.31"/>
  </joint>
  <link name="global_camera_link">
    <visual>
      <geometry>
        <box size="0.08 0.25 0.05"/>
      </geometry>
      <origin rpy="0 0 0" xyz="0.0 0.0 0.0"/>
      <material name="LightBlue"/>
    </visual>
    <collision>
      <geometry>
        <box size="0.08 0.25 0.05"/>
      </geometry>
      <origin rpy="0 0 0" xyz="0.0 0.0 0.0"/>
      <material name="LightBlue"/>
    </collision>
  </link>
  <link name="base_link">
    <visual>
      <geometry>
        <mesh filename="package://ur_description/meshes/ur5/visual/base.dae"/>
      </geometry>
      <material name="LightGrey">
        <color rgba="0.7 0.7 0.7 1.0"/>
      </material>
    </visual>
    <collision>
      <geometry>
        <mesh filename="package://ur_description/meshes/ur5/collision/base.stl"/>
      </geometry>
    </collision>
    <inertial>
      <mass value="4.0"/>
      <origin rpy="0 0 0" xyz="0.0 0.0 0.0"/>
      <inertia ixx="0.00443333156" ixy="0.0" ixz="0.0" iyy="0.00443333156" iyz="0.0" izz="0.0072"/>
    </inertial>
  </link>
  <joint name="shoulder_pan_joint" type="revolute">
    <parent link="base_link"/>
    <child link="shoulder_link"/>
    <origin rpy="0.0 0.0 0.0" xyz="0.0 0.0 0.089159"/>
    <axis xyz="0 0 1"/>
    <limit effort="150.0" lower="-6.2831853" upper="6.2831853" velocity="3.15"/>
    <dynamics damping="0.0" friction="0.0"/>
  </joint>
  <link name="shoulder_link">
    <visual>
      <geometry>
        <mesh filename="package://ur_description/meshes/ur5/visual/shoulder.dae"/>
      </geometry>
      <material name="LightGrey">
        <color rgba="0.7 0.7 0.7 1.0"/>
      </material>
    </visual>
    <collision>
      <geometry>
        <mesh filename="package://ur_description/meshes/ur5/collision/shoulder.stl"/>
      </geometry>
    </collision>
    <inertial>
      <mass value="3.7"/>
      <origin rpy="0 0 0" xyz="0.0 0.0 0.0"/>
      <inertia ixx="0.010267495893" ixy="0.0" ixz="0.0" iyy="0.010267495893" iyz="0.0" izz="0.00666"/>
    </inertial>
  </link>
  <joint name="shoulder_lift_joint" type="revolute">
    <parent link="shoulder_link"/>
    <child link="upper_arm_link"/>
    <origin rpy="0.0 1.570796325 0.0" xyz="0.0 0.13585 0.0"/>
    <axis xyz="0 1 0"/>
    <limit effort="150.0" lower="-6.2831853" upper="6.2831853" velocity="3.15"/>
    <dynamics damping="0.0" friction="0.0"/>
  </joint>
  <link name="upper_arm_link">
    <visual>
      <geometry>
        <mesh filename="package://ur_description/meshes/ur5/visual/upperarm.dae"/>
      </geometry>
      <material name="LightGrey">
        <color rgba="0.7 0.7 0.7 1.0"/>
      </material>
    </visual>
    <collision>
      <geometry>
        <mesh filename="package://ur_description/meshes/ur5/collision/upperarm.stl"/>
      </geometry>
    </collision>
    <inertial>
      <mass value="8.393"/>
      <origin rpy="0 0 0" xyz="0.0 0.0 0.28"/>
      <inertia ixx="0.22689067591" ixy="0.0" ixz="0.0" iyy="0.22689067591" iyz="0.0" izz="0.0151074"/>
    </inertial>
  </link>
  <joint name="elbow_joint" type="revolute">
    <parent link="upper_arm_link"/>
    <child link="forearm_link"/>
    <origin rpy="0.0 0.0 0.0" xyz="0.0 -0.1197 0.425"/>
    <axis xyz="0 1 0"/>
    <limit effort="150.0" lower="-6.2831853" upper="6.2831853" velocity="3.15"/>
    <dynamics damping="0.0" friction="0.0"/>
  </joint>
  <link name="forearm_link">
    <visual>
      <geometry>
        <mesh filename="package://ur_description/meshes/ur5/visual/forearm.dae"/>
      </geometry>
      <material name="LightGrey">
        <color rgba="0.7 0.7 0.7 1.0"/>
      </material>
    </visual>
    <collision>
      <geometry>
        <mesh filename="package://ur_description/meshes/ur5/collision/forearm.stl"/>
      </geometry>
    </collision>
    <inertial>
      <mass value="2.275"/>
      <origin rpy="0 0 0" xyz="0.0 0.0 0.25"/>
      <inertia ixx="0.049443313556" ixy="0.0" ixz="0.0" iyy="0.049443313556" iyz="0.0" izz="0.004095"/>
    </inertial>
  </link>
  <joint name="wrist_1_joint" type="revolute">
    <parent link="forearm_link"/>
    <child link="wrist_1_link"/>
    <origin rpy="0.0 1.570796325 0.0" xyz="0.0 0.0 0.39225"/>
    <axis xyz="0 1 0"/>
    <limit effort="28.0" lower="-6.2831853" upper="6.2831853" velocity="3.2"/>
    <dynamics damping="0.0" friction="0.0"/>
  </joint>
  <link name="wrist_1_link">
    <visual>
      <geometry>
        <mesh filename="package://ur_description/meshes/ur5/visual/wrist1.dae"/>
      </geometry>
      <material name="LightGrey">
        <color rgba="0.7 0.7 0.7 1.0"/>
      </material>
    </visual>
    <collision>
      <geometry>
        <mesh filename="package://ur_description/meshes/ur5/collision/wrist1.stl"/>
      </geometry>
    </collision>
    <inertial>
      <mass value="1.219"/>
      <origin rpy="0 0 0" xyz="0.0 0.0 0.0"/>
      <inertia ixx="0.111172755531" ixy="0.0" ixz="0.0" iyy="0.111172755531" iyz="0.0" izz="0.21942"/>
    </inertial>
  </link>
  <joint name="wrist_2_joint" type="revolute">
    <parent link="wrist_1_link"/>
    <child link="wrist_2_link"/>
    <origin rpy="0.0 0.0 0.0" xyz="0.0 0.093 0.0"/>
    <axis xyz="0 0 1"/>
    <limit effort="28.0" lower="-6.2831853" upper="6.2831853" velocity="3.2"/>
    <dynamics damping="0.0" friction="0.0"/>
  </joint>
  <link name="wrist_2_link">
    <visual>
      <geometry>
        <mesh filename="package://ur_description/meshes/ur5/visual/wrist2.dae"/>
      </geometry>
      <material name="LightGrey">
        <color rgba="0.7 0.7 0.7 1.0"/>
      </material>
    </visual>
    <collision>
      <geometry>
        <mesh filename="package://ur_description/meshes/ur5/collision/wrist2.stl"/>
      </geometry>
    </collision>
    <inertial>
      <mass value="1.219"/>
      <origin rpy="0 0 0" xyz="0.0 0.0 0.0"/>
      <inertia ixx="0.111172755531" ixy="0.0" ixz="0.0" iyy="0.111172755531" iyz="0.0" izz="0.21942"/>
    </inertial>
  </link>
  <joint name="wrist_3_joint" type="revolute">
    <parent link="wrist_2_link"/>
    <child link="wrist_3_link"/>
    <origin rpy="0.0 0.0 0.0" xyz="0.0 0.0 0.09465"/>
    <axis xyz="0 1 0"/>
    <limit effort="28.0" lower="-6.2831853" upper="6.2831853" velocity="3.2"/>
    <dynamics damping="0.0" friction="0.0"/>
  </joint>
  <link name="wrist_3_link">
    <visual>
      <geometry>
        <mesh filename="package://ur_description/meshes/ur5/visual/wrist3.dae"/>
      </geometry>
      <material name="LightGrey">
        <color rgba="0.7 0.7 0.7 1.0"/>
      </material>
    </visual>
    <collision>
      <geometry>
        <mesh filename="package://ur_description/meshes/ur5/collision/wrist3.stl"/>
      </geometry>
    </collision>
    <inertial>
      <mass value="0.1879"/>
      <origin rpy="0 0 0" xyz="0.0 0.0 0.0"/>
      <inertia ixx="0.0171364731454" ixy="0.0" ixz="0.0" iyy="0.0171364731454" iyz="0.0" izz="0.033822"/>
    </inertial>
  </link>
  <joint name="ee_fixed_joint" type="fixed">
    <parent link="wrist_3_link"/>
    <child link="ee_link"/>
    <origin rpy="0.0 0.0 1.570796325" xyz="0.0 0.0823 0.0"/>
  </joint>
  <link name="ee_link">
    <collision>
      <geometry>
        <box size="0.01 0.01 0.01"/>
      </geometry>
      <origin rpy="0 0 0" xyz="-0.01 0 0"/>
    </collision>
  </link>
  <transmission name="shoulder_pan_trans">
    <type>transmission_interface/SimpleTransmission</type>
    <joint name="shoulder_pan_joint">
      <hardwareInterface>PositionJointInterface</hardwareInterface>
    </joint>
    <actuator name="shoulder_pan_motor">
      <mechanicalReduction>1</mechanicalReduction>
    </actuator>
  </transmission>
  <transmission name="shoulder_lift_trans">
    <type>transmission_interface/SimpleTransmission</type>
    <joint name="shoulder_lift_joint">
      <hardwareInterface>PositionJointInterface</hardwareInterface>
    </joint>
    <actuator name="shoulder_lift_motor">
      <mechanicalReduction>1</mechanicalReduction>
    </actuator>
  </transmission>
  <transmission name="elbow_trans">
    <type>transmission_interface/SimpleTransmission</type>
    <joint name="elbow_joint">
      <hardwareInterface>PositionJointInterface</hardwareInterface>
    </joint>
    <actuator name="elbow_motor">
      <mechanicalReduction>1</mechanicalReduction>
    </actuator>
  </transmission>
  <transmission name="wrist_1_trans">
    <type>transmission_interface/SimpleTransmission</type>
    <joint name="wrist_1_joint">
      <hardwareInterface>PositionJointInterface</hardwareInterface>
    </joint>
    <actuator name="wrist_1_motor">
      <mechanicalReduction>1</mechanicalReduction>
    </actuator>
  </transmission>
  <transmission name="wrist_2_trans">
    <type>transmission_interface/SimpleTransmission</type>
    <joint name="wrist_2_joint">
      <hardwareInterface>PositionJointInterface</hardwareInterface>
    </joint>
    <actuator name="wrist_2_motor">
      <mechanicalReduction>1</mechanicalReduction>
    </actuator>
  </transmission>
  <transmission name="wrist_3_trans">
    <type>transmission_interface/SimpleTransmission</type>
    <joint name="wrist_3_joint">
      <hardwareInterface>PositionJointInterface</hardwareInterface>
    </joint>
    <actuator name="wrist_3_motor">
      <mechanicalReduction>1</mechanicalReduction>
    </actuator>
  </transmission>
  
  <joint name="wrist_3_link-tool0_fixed_joint" type="fixed">
    <origin rpy="-1.570796325 0 0" xyz="0 0.0823 0"/>
    <parent link="wrist_3_link"/>
    <child link="tool0"/>
  </joint>
  <link name="tool0"/>

  <!-- ========== Add dorahand here ========== -->

  <joint name="dh_hand_link-tool0_fixed_joint" type="fixed">
    <origin rpy="1.570796325 -1.570796325 1.570796325" xyz="0 0 0"/>
    <parent link="tool0"/>
    <child link="dh_hand_link"/>
  </joint>


  <joint name="last_joint" type="fixed">
    <origin rpy="1.570796325 0 1.570796325" xyz="0.21 0 0.04"/>
    <parent link="dh_hand_link"/>
    <child link="gripper_ee_link"/>
  </joint>

  <link name="gripper_ee_link">
  </link>

  <link name="dh_hand_link">
    <visual>
      <geometry>
        <mesh filename="package://robot_bringup/description/dorahand_model/dorahand.obj"/>
      </geometry>
    </visual>
    <collision>
      <geometry>
        <mesh filename="package://robot_bringup/description/dorahand_model/dorahand_simple.obj"/>
      </geometry>
    </collision>
  </link>

  <!-- ========== Add dorahand over ========== -->

  <joint name="arm_lift_joint" type="fixed">
    <parent link="lift_move_link"/>
    <child link="base_link"/>
    <origin rpy="0.0 0.0 0.0" xyz="0.0 0.0 0.37"/>
  </joint>


 </robot>
